{
 "cells": [
  {
   "cell_type": "code",
   "execution_count": 1,
   "metadata": {},
   "outputs": [
    {
     "name": "stderr",
     "output_type": "stream",
     "text": [
      "c:\\Users\\Frederick\\anaconda3\\envs\\EmbeddingLearning\\Lib\\site-packages\\tqdm\\auto.py:21: TqdmWarning: IProgress not found. Please update jupyter and ipywidgets. See https://ipywidgets.readthedocs.io/en/stable/user_install.html\n",
      "  from .autonotebook import tqdm as notebook_tqdm\n"
     ]
    }
   ],
   "source": [
    "# Load model directly\n",
    "from transformers import AutoTokenizer, AutoModelForSeq2SeqLM\n",
    "\n",
    "tokenizer = AutoTokenizer.from_pretrained(\"indonlp/cendol-mt5-small-chat\")\n",
    "model = AutoModelForSeq2SeqLM.from_pretrained(\"indonlp/cendol-mt5-small-chat\")"
   ]
  },
  {
   "cell_type": "code",
   "execution_count": 2,
   "metadata": {},
   "outputs": [],
   "source": [
    "import PyPDF2\n",
    "\n",
    "def extract_text_from_pdf(pdf_file):\n",
    "    with open(pdf_file, 'rb') as file:\n",
    "        reader = PyPDF2.PdfReader(file)\n",
    "        text = \"\"\n",
    "        for page in reader.pages:\n",
    "            text += page.extract_text()\n",
    "    return text"
   ]
  },
  {
   "cell_type": "code",
   "execution_count": 8,
   "metadata": {},
   "outputs": [
    {
     "name": "stdout",
     "output_type": "stream",
     "text": [
      "Unexpected exception formatting exception. Falling back to standard exception\n"
     ]
    },
    {
     "name": "stderr",
     "output_type": "stream",
     "text": [
      "Traceback (most recent call last):\n",
      "  File \"c:\\Users\\Frederick\\anaconda3\\lib\\site-packages\\transformers\\utils\\import_utils.py\", line 1364, in _get_module\n",
      "    {0} requires the timm library but it was not found in your environment. You can install it with pip:\n",
      "  File \"c:\\Users\\Frederick\\anaconda3\\lib\\importlib\\__init__.py\", line 126, in import_module\n",
      "    return _bootstrap._gcd_import(name[level:], package, level)\n",
      "  File \"<frozen importlib._bootstrap>\", line 1050, in _gcd_import\n",
      "  File \"<frozen importlib._bootstrap>\", line 1027, in _find_and_load\n",
      "  File \"<frozen importlib._bootstrap>\", line 1006, in _find_and_load_unlocked\n",
      "  File \"<frozen importlib._bootstrap>\", line 688, in _load_unlocked\n",
      "  File \"<frozen importlib._bootstrap_external>\", line 883, in exec_module\n",
      "  File \"<frozen importlib._bootstrap>\", line 241, in _call_with_frames_removed\n",
      "  File \"c:\\Users\\Frederick\\anaconda3\\lib\\site-packages\\transformers\\trainer_callback.py\", line 28, in <module>\n",
      "    from .training_args import TrainingArguments\n",
      "  File \"c:\\Users\\Frederick\\anaconda3\\lib\\site-packages\\transformers\\training_args.py\", line 38, in <module>\n",
      "    from .utils import (\n",
      "ImportError: cannot import name 'is_torch_mlu_available' from 'transformers.utils' (c:\\Users\\Frederick\\anaconda3\\lib\\site-packages\\transformers\\utils\\__init__.py)\n",
      "\n",
      "The above exception was the direct cause of the following exception:\n",
      "\n",
      "Traceback (most recent call last):\n",
      "  File \"c:\\Users\\Frederick\\anaconda3\\lib\\site-packages\\IPython\\core\\interactiveshell.py\", line 3553, in run_code\n",
      "    exec(code_obj, self.user_global_ns, self.user_ns)\n",
      "  File \"C:\\Users\\Frederick\\AppData\\Local\\Temp\\ipykernel_22748\\1401562161.py\", line 1, in <module>\n",
      "    from sentence_transformers import SentenceTransformer\n",
      "  File \"c:\\Users\\Frederick\\anaconda3\\lib\\site-packages\\sentence_transformers\\__init__.py\", line 9, in <module>\n",
      "    from sentence_transformers.cross_encoder.CrossEncoder import CrossEncoder\n",
      "  File \"c:\\Users\\Frederick\\anaconda3\\lib\\site-packages\\sentence_transformers\\cross_encoder\\__init__.py\", line 3, in <module>\n",
      "    from .CrossEncoder import CrossEncoder\n",
      "  File \"c:\\Users\\Frederick\\anaconda3\\lib\\site-packages\\sentence_transformers\\cross_encoder\\CrossEncoder.py\", line 20, in <module>\n",
      "    from sentence_transformers.SentenceTransformer import SentenceTransformer\n",
      "  File \"c:\\Users\\Frederick\\anaconda3\\lib\\site-packages\\sentence_transformers\\SentenceTransformer.py\", line 32, in <module>\n",
      "    from sentence_transformers.model_card import SentenceTransformerModelCardData, generate_model_card\n",
      "  File \"c:\\Users\\Frederick\\anaconda3\\lib\\site-packages\\sentence_transformers\\model_card.py\", line 24, in <module>\n",
      "    from transformers import TrainerCallback\n",
      "  File \"<frozen importlib._bootstrap>\", line 1075, in _handle_fromlist\n",
      "  File \"c:\\Users\\Frederick\\anaconda3\\lib\\site-packages\\transformers\\utils\\import_utils.py\", line 1354, in __getattr__\n",
      "  File \"c:\\Users\\Frederick\\anaconda3\\lib\\site-packages\\transformers\\utils\\import_utils.py\", line 1366, in _get_module\n",
      "    \"\"\"\n",
      "RuntimeError: Failed to import transformers.trainer_callback because of the following error (look up to see its traceback):\n",
      "cannot import name 'is_torch_mlu_available' from 'transformers.utils' (c:\\Users\\Frederick\\anaconda3\\lib\\site-packages\\transformers\\utils\\__init__.py)\n",
      "\n",
      "During handling of the above exception, another exception occurred:\n",
      "\n",
      "Traceback (most recent call last):\n",
      "  File \"c:\\Users\\Frederick\\anaconda3\\lib\\site-packages\\IPython\\core\\interactiveshell.py\", line 2144, in showtraceback\n",
      "    stb = self.InteractiveTB.structured_traceback(\n",
      "  File \"c:\\Users\\Frederick\\anaconda3\\lib\\site-packages\\IPython\\core\\ultratb.py\", line 1435, in structured_traceback\n",
      "    return FormattedTB.structured_traceback(\n",
      "  File \"c:\\Users\\Frederick\\anaconda3\\lib\\site-packages\\IPython\\core\\ultratb.py\", line 1326, in structured_traceback\n",
      "    return VerboseTB.structured_traceback(\n",
      "  File \"c:\\Users\\Frederick\\anaconda3\\lib\\site-packages\\IPython\\core\\ultratb.py\", line 1173, in structured_traceback\n",
      "    formatted_exception = self.format_exception_as_a_whole(etype, evalue, etb, number_of_lines_of_context,\n",
      "  File \"c:\\Users\\Frederick\\anaconda3\\lib\\site-packages\\IPython\\core\\ultratb.py\", line 1088, in format_exception_as_a_whole\n",
      "    frames.append(self.format_record(record))\n",
      "  File \"c:\\Users\\Frederick\\anaconda3\\lib\\site-packages\\IPython\\core\\ultratb.py\", line 970, in format_record\n",
      "    frame_info.lines, Colors, self.has_colors, lvals\n",
      "  File \"c:\\Users\\Frederick\\anaconda3\\lib\\site-packages\\IPython\\core\\ultratb.py\", line 792, in lines\n",
      "    return self._sd.lines\n",
      "  File \"c:\\Users\\Frederick\\anaconda3\\lib\\site-packages\\stack_data\\utils.py\", line 145, in cached_property_wrapper\n",
      "    value = obj.__dict__[self.func.__name__] = self.func(obj)\n",
      "  File \"c:\\Users\\Frederick\\anaconda3\\lib\\site-packages\\stack_data\\core.py\", line 698, in lines\n",
      "    pieces = self.included_pieces\n",
      "  File \"c:\\Users\\Frederick\\anaconda3\\lib\\site-packages\\stack_data\\utils.py\", line 145, in cached_property_wrapper\n",
      "    value = obj.__dict__[self.func.__name__] = self.func(obj)\n",
      "  File \"c:\\Users\\Frederick\\anaconda3\\lib\\site-packages\\stack_data\\core.py\", line 649, in included_pieces\n",
      "    pos = scope_pieces.index(self.executing_piece)\n",
      "  File \"c:\\Users\\Frederick\\anaconda3\\lib\\site-packages\\stack_data\\utils.py\", line 145, in cached_property_wrapper\n",
      "    value = obj.__dict__[self.func.__name__] = self.func(obj)\n",
      "  File \"c:\\Users\\Frederick\\anaconda3\\lib\\site-packages\\stack_data\\core.py\", line 628, in executing_piece\n",
      "    return only(\n",
      "  File \"c:\\Users\\Frederick\\anaconda3\\lib\\site-packages\\executing\\executing.py\", line 164, in only\n",
      "    raise NotOneValueFound('Expected one value, found 0')\n",
      "executing.executing.NotOneValueFound: Expected one value, found 0\n"
     ]
    }
   ],
   "source": [
    "from sentence_transformers import SentenceTransformer\n",
    "\n",
    "EmbeddingModel = SentenceTransformer('paraphrase-MiniLM-L6-v2')\n",
    "\n",
    "def generate_embeddings(text):\n",
    "    sentences = text.split(\". \")  \n",
    "    embeddings = EmbeddingModel.encode(sentences, convert_to_tensor=True)\n",
    "    return sentences, embeddings\n"
   ]
  }
 ],
 "metadata": {
  "kernelspec": {
   "display_name": "base",
   "language": "python",
   "name": "python3"
  },
  "language_info": {
   "codemirror_mode": {
    "name": "ipython",
    "version": 3
   },
   "file_extension": ".py",
   "mimetype": "text/x-python",
   "name": "python",
   "nbconvert_exporter": "python",
   "pygments_lexer": "ipython3",
   "version": "3.12.5"
  }
 },
 "nbformat": 4,
 "nbformat_minor": 2
}
